#VRML_SIM R2021a utf8
WorldInfo {
}
Viewpoint {
  orientation -0.7070360622586778 0.014142606976391622 -0.7070360622582519 0.05656665674485169
  position -0.09353453917903876 1.0524860294339264 24.01299232404559
}
TexturedBackground {
}
TexturedBackgroundLight {
}
RectangleArena {
  rotation 1 0 0 1.5708
  floorSize 10 10
  floorTileSize 1 1
}
Wall {
  translation -1 -4 0
  rotation 1 0 0 1.5708
  size 4 2 0.1
}
Wall {
  translation -4 -1.5 0
  rotation 1 0 0 1.5708
  name "wall(1)"
  size 2 2 0.1
}
Wall {
  translation -3 -4.5 0
  rotation 0.5773509358554485 0.5773489358556708 0.5773509358554485 2.0944
  name "wall(2)"
  size 1 2 0.1
}
Wall {
  translation 3.25 0.5 0
  rotation 1 0 0 1.5708
  name "wall(4)"
  size 1.5 2 0.1
}
Wall {
  translation 3 3.5 0
  rotation 1 0 0 1.5708
  name "wall(8)"
  size 4 2 0.1
}
Wall {
  translation 3.25 2 0
  rotation 1 0 0 1.5708
  name "wall(11)"
  size 1.5 2 0.1
}
Wall {
  translation 4 1.25 0
  rotation 0.5773509358554485 0.5773489358556708 0.5773509358554485 2.0944
  name "wall(12)"
  size 1.5 2 0.1
}
Wall {
  translation -3 -2 0
  rotation 0.5773509358554485 0.5773489358556708 0.5773509358554485 2.0944
  name "wall(6)"
  size 1 2 0.1
}
Wall {
  translation -0.499992 2.03 -1.11441e-05
  rotation 1.6952594753969508e-09 0.707104781184338 0.7071087811831002 -3.1415853071795863
  name "wall(13)"
  size 1 2 0.1
}
Wall {
  translation 1.07 0.99 -1.33174e-06
  rotation 0.5773509358554485 0.5773489358556708 0.5773509358554485 2.0944
  name "wall(14)"
  size 5 2 0.1
}
Wall {
  translation -0.25 -2.5 0
  rotation 1 0 0 1.5708
  name "wall(15)"
  size 5.5 2 0.1
}
Wall {
  translation 2.5 -1.5 0
  rotation 0.5773509358554485 0.5773489358556708 0.5773509358554485 2.0944
  name "wall(16)"
  size 2 2 0.1
}
Wall {
  translation 3.75 -3 0
  rotation 0.5773509358554485 0.5773489358556708 0.5773509358554485 2.0944
  name "wall(3)"
  size 4 2 0.1
}
Wall {
  translation -1 -1.5 0
  rotation 1 0 0 1.5708
  name "wall(5)"
  size 2 2 0.1
}
Wall {
  translation -3.5 3 0
  rotation 0.5773509358554485 0.5773489358556708 0.5773509358554485 2.0944
  name "wall(21)"
  size 1 2 0.1
}
Wall {
  translation -2 -0.5 0
  rotation 1.6952594753969508e-09 0.707104781184338 0.7071087811831002 -3.1415853071795863
  name "wall(22)"
  size 3 2 0.1
}
Wall {
  translation -2 2 0
  rotation 0.5773509358554485 0.5773489358556708 0.5773509358554485 2.0944
  name "wall(23)"
  size 3 2 0.1
}
Wall {
  translation -0.5 1 0
  rotation 1.6952594753969508e-09 0.707104781184338 0.7071087811831002 -3.1415853071795863
  name "wall(25)"
  size 1 2 0.1
}
Wall {
  translation -0.5 3.5 0
  rotation 0.5773509358554485 0.5773489358556708 0.5773509358554485 2.0944
  name "wall(26)"
  size 3 2 0.1
}
Wall {
  translation -3.5 3.5 0
  rotation 1 0 0 1.5708
  name "wall(27)"
  size 3 2 0.1
}
Wall {
  translation -3.5 0.5 0
  rotation 0.5773509358554485 0.5773489358556708 0.5773509358554485 2.0944
  name "wall(29)"
  size 2 2 0.1
}
Robot {
  translation 4.5 4.5 0.039697
  rotation -6.253085749538536e-06 1.7812633049990147e-06 -0.999999999978863 -0.5529227670634482
  children [
    Lidar {
      translation 0 0 0.06
      rotation 0.5773509358554485 0.5773489358556708 0.5773509358554485 2.0943999999999994
      numberOfLayers 1
      maxRange 5
      type "rotating"
    }
    GPS {
    }
    GPS {
      translation 0.05 0 0
      name "head_gps"
    }
    InertialUnit {
      rotation 0 0 1 1.5708
    }
    HingeJoint {
      jointParameters HingeJointParameters {
        position -1.13599454856823
        axis 0 1 0
        anchor 0.06 0.07 0
      }
      device [
        RotationalMotor {
          name "motor1"
          maxVelocity 20
        }
      ]
      endPoint Solid {
        translation 0.06000000000000011 0.07000000000000028 2.5446701177106256e-16
        rotation 0 -1 0 1.13599454856823
        children [
          DEF WHEEL Shape {
            geometry Cylinder {
              height 0.03
              radius 0.04
            }
          }
        ]
        boundingObject USE WHEEL
        physics Physics {
        }
      }
    }
    HingeJoint {
      jointParameters HingeJointParameters {
        position -1.135995483805034
        axis 0 1 0
        anchor -0.06 0.07 0
      }
      device [
        RotationalMotor {
          name "motor2"
          maxVelocity 20
        }
      ]
      endPoint Solid {
        translation -0.05999999999999993 0.07000000000000028 1.5139111063865173e-16
        rotation 0 -0.9999999999999999 0 1.1359954838050341
        children [
          Shape {
            geometry Cylinder {
              height 0.03
              radius 0.04
            }
          }
        ]
        name "solid(1)"
        boundingObject USE WHEEL
        physics Physics {
        }
      }
    }
    HingeJoint {
      jointParameters HingeJointParameters {
        position 1.7759954812697414
        axis 0 1 0
        anchor 0.06 -0.07 0
      }
      device [
        RotationalMotor {
          name "motor3"
          maxVelocity 20
        }
      ]
      endPoint Solid {
        translation 0.05999999999999999 -0.06999999999999984 -5.525652585356273e-17
        rotation 0 1 0 1.7759954812697414
        children [
          Shape {
            geometry Cylinder {
              height 0.03
              radius 0.04
            }
          }
        ]
        name "solid(2)"
        boundingObject USE WHEEL
        physics Physics {
        }
      }
    }
    HingeJoint {
      jointParameters HingeJointParameters {
        position 1.7759945433126099
        axis 0 1 0
        anchor -0.06 -0.07 0
      }
      device [
        RotationalMotor {
          name "motor4"
          maxVelocity 20
        }
      ]
      endPoint Solid {
        translation -0.060000000000000026 -0.06999999999999984 -1.643253893120383e-16
        rotation 0 1 0 1.7759945433126099
        children [
          Shape {
            geometry Cylinder {
              height 0.03
              radius 0.04
            }
          }
        ]
        name "solid(3)"
        boundingObject USE WHEEL
        physics Physics {
        }
      }
    }
    DEF BODY Shape {
      appearance PBRAppearance {
      }
      geometry Box {
        size 0.2 0.1 0.05
      }
    }
  ]
  name "robot(1)"
  boundingObject USE BODY
  physics Physics {
    density -1
    mass 1
  }
  controller "my_controller"
}
